<mujoco>
  <compiler autolimits="true" assetdir="assets"/>
  <statistic center="0 0 0.1" extent="0.6" meansize=".05"/>
  <option gravity="0 0 -9.8" viscosity="0.01" wind="2.5 0.2 0.5" />
  <!-- <option gravity="0 0 -9.8" viscosity="0.01" wind="0 0 0" /> -->

  <default>
    <motor ctrlrange="0 13"/>
    <default class="x2">
      <geom mass="0"/>
      <mesh scale="0.01 0.01 0.01"/>
      <default class="visual">
        <geom group="2" type="mesh" contype="0" conaffinity="0"/>
      </default>
      <default class="collision">
        <geom group="3" type="box"/>
        <default class="rotor">
          <geom type="ellipsoid" size=".13 .13 .01"/>
        </default>
      </default>
      <site group="5"/>
    </default>
  </default>


  <visual>
    <headlight diffuse="0.6 0.6 0.6" ambient="0.3 0.3 0.3" specular="0 0 0"/>
    <rgba haze="0.15 0.25 0.35 1"/>
    <global azimuth="-20" elevation="-20" ellipsoidinertia="true"/>
  </visual>

  <asset>
    <texture type="skybox" builtin="gradient" rgb1="0.3 0.5 0.7" rgb2="0 0 0" width="512" height="30720"/>
    <texture type="2d" name="groundplane" builtin="checker" mark="edge" rgb1="0.2 0.3 0.4" rgb2="0.1 0.2 0.3"
      markrgb="0.8 0.8 0.8" width="300" height="300"/>
    <material name="groundplane" texture="groundplane" texuniform="true" texrepeat="5 5" reflectance="0.2"/>

          <mesh file="Gondola v9.obj" />
  </asset>

  <worldbody>
    <light pos="0 0 1.5" dir="0 0 -1" directional="true"/>
    <geom name="floor" size="0 0 0.05" type="plane" material="groundplane"/>
  </worldbody>


  <compiler angle="degree" coordinate="local" inertiafromgeom="true"/>

  <!-- <default> -->
  <!--   <joint damping="0.03" actuatorfrcrange="-0.5 0.5"/> -->
  <!-- </default> -->
  <!---->
  <worldbody>

    <body name="blloon" pos="0 0 0.5" gravcomp="4" >
      <freejoint/>
      <geom name="mylar" type="ellipsoid" size="0.35 0.35 0.20" rgba="1 0 0 1" mass="0.25"/>
      <geom  mesh="Gondola v9" class="visual" quat="0 0 1 1"/>
      <site name="imu" pos="0 0 .02"/>
      <body name="m1" pos="0 0 0.2" >
        <geom name="body" type="cylinder" size="0.04 0.05 0.02" rgba="1 0.753 0.796 0.7" mass="0.8" />
        <body name="prop" pos="0 0 0.05" >
          <joint type="hinge" name="prop_joint" />
          <geom name="prop" type="ellipsoid" size="0.012 0.001 0.20" rgba="1 0.753 0.796 1" euler="90 0 0" />
        <site name="thrust1" pos="0 0 0" />
        </body>

    </body>
    </body>

  </worldbody>

  <actuator>
    <motor name="prop_joint" site="thrust1" gear="0 0 1 0 0 -.301" />
  </actuator>

   <sensor>
    <gyro name="body_gyro" site="imu"/>
    <accelerometer name="body_linacc" site="imu"/>
    <framequat name="body_quat" objtype="site" objname="imu"/>
  </sensor>

</mujoco>
