<mujoco>
  <compiler assetdir="assets" />
  <!-- <statistic center="0 0 0.1" extent="0.6" meansize=".05"/> -->
  <!-- <option gravity="0 0 -9.8" viscosity="0.01" wind="2.5 0.2 0.5" /> -->
  <!-- <option gravity="0 0 -9.8"  /> -->
  <option density="1.204" viscosity="1.8e-5" integrator="implicit"/>

  <default>
    <motor ctrlrange="-10 10" />
    <default class="imported">
      <mesh scale="0.001 0.001 0.001" />
    </default>
    <default class="collision">
      <geom group="3" type="box" />
    </default>
    <default class="balloon">
      <!--
        0.167 is the MKS density of helium at room temperature.
        Note this does not take into account the mass of the rubber,
        which is likely not insignificant.
      -->
      <geom density="0.167" fluidshape="ellipsoid" />
      <default class="pink">
        <geom rgba="1 .6 .7 1" />
        <site rgba="1 .6 .7 1" />
      </default>
      <default class="blue">
        <geom rgba=".3 .7 .9 1" />
        <site rgba=".3 .7 .9 1" />
      </default>
      <default class="green">
        <geom rgba=".4 .9 .5 1" />
        <site rgba=".4 .9 .5 1" />
      </default>
      <default class="orange">
        <geom rgba="1 .4 0 1" />
        <site rgba="1 .4 0 1" />
      </default>
    </default>
    <!-- <site group="5"/> -->
  </default>

  <visual>
    <headlight diffuse="0.6 0.6 0.6" ambient="0.3 0.3 0.3" specular="0 0 0" />
    <rgba haze="0.15 0.25 0.35 1" />
    <global azimuth="-20" elevation="-20" ellipsoidinertia="true" />
  </visual>

  <asset>
    <texture type="skybox" builtin="gradient" rgb1="0.3 0.5 0.7" rgb2="0 0 0" width="512"
      height="30720" />
    <texture type="2d" name="groundplane" builtin="checker" mark="edge" rgb1="0.2 0.3 0.4"
      rgb2="0.1 0.2 0.3"
      markrgb="0.8 0.8 0.8" width="300" height="300" />
    <material name="groundplane" texture="groundplane" texuniform="true" texrepeat="5 5"
      reflectance="0.2" />

    <mesh file="Gondola.obj" class="imported" />
    <mesh file="MotorMount.obj" class="imported" />
    <mesh file="MotorMountHolder.obj" class="imported" />
    <mesh file="Motor v1.obj" class="imported" />
  </asset>

  <worldbody>
    <light pos="0 0 1.5" dir="0 0 -1" directional="true" />
    <geom name="floor" size="0 0 0.05" type="plane" material="groundplane" />
  </worldbody>


  <compiler angle="degree" coordinate="local" inertiafromgeom="true" />

  <worldbody>

    <body childclass="pink" gravcomp="7.2" pos="0 0 .5">
      <freejoint />
      <geom name="mylar" type="ellipsoid" size="0.35 0.35 0.20" rgba="0.6 0 0 1" />
      <site name="mountBalloon4" pos = "-0.020 -0.034 -0.2" ></site>
      <site name="mountBalloon2" pos = "0.020 0.035 -0.2"></site>
      <site name="mountBalloon3" pos = "-.020 0.034 -0.2"></site>
      <site name="mountBalloon1" pos = "0.020 -0.035 -0.2"></site>
    </body>

    <body name="gondola" pos="0 0 0" quat="0 1 0 0" gravcomp="1.1">
      <freejoint/>
      <geom type="mesh" mesh="Gondola" pos="0 0 0" quat="0 1 0 0" />
      <body name="m1" pos="0.020 0.035 0" quat="0 1 0.45 0">
      <site name="mountGondola1" pos="0 0 0.0"/>
        <geom type="mesh" mesh="MotorMountHolder" name="m1" />
        <body name="polpusion" pos="0.005 0.005 -0.024" euler="90 0 0">
          <geom type="mesh" mesh="Motor v1" />
          <body name="propeller" pos="0 0 0.021">
            <joint type="hinge" name="prop_joint" damping="0.03" axis="0 0 1" />
            <site name="thrust1" pos="0 0 0" />
            <geom type="ellipsoid" size="0.0025 0.015 0.001" euler="0 0 45 " rgba="0 0 1 1" />
          </body>
        </body>
      </body>
      <body name="m2" pos="0.020 -0.035 0" quat="0 1 -0.45 0">
        <geom type="mesh" mesh="MotorMountHolder" name="m2" mass="0.08" />
      <site name="mountGondola2" pos="0 0 0.0"/>
        <body name="polpusion2" pos="0.005 -0.005 -0.024" euler="90 45 0">
          <geom type="mesh" mesh="Motor v1" euler="0 135 0" />
          <body name="propeller2" pos="0.015 0 -0.015" euler="0 135 0">
            <joint type="hinge" name="prop_joint2" damping="0.03" axis="0 0 1" />
            <geom type="ellipsoid" size="0.0025 0.015 0.001" rgba="0 1 0 1" />
            <site name="thrust2" pos="0 0 0" />
          </body>
        </body>
      </body>

      <body name="m3" pos="-0.020 -0.034 0" quat="0 -1 2 0">
        <geom type="mesh" mesh="MotorMountHolder" name="m3" />
      <site name="mountGondola3" pos="0 0 0.0"/>
        <body name="polpusion3" pos="0.005 0.005 -0.024" euler="90 45 0">
          <geom type="mesh" mesh="Motor v1" euler="0 -45 0" />
          <body name="propeller3" pos="-0.015 0 0.015" euler="0 -45 0">
            <joint type="hinge" name="prop_joint3" damping="0.03" axis="0 0 1" />
            <geom type="ellipsoid" size="0.0025 0.015 0.001" rgba="0 1 0 1" />
            <site name="thrust3" pos="0 0 0" />
          </body>
        </body>
      </body>

      <body name="m4" pos="-0.020 0.035 0" quat="0 0.2 0.45 0">
        <geom type="mesh" mesh="MotorMountHolder" name="m4" mass="0.08" />
      <site name="mountGondola4" pos="0 0 0.0"/>
        <body name="polpusion4" pos="0.005 -0.005 -0.024" euler="-90 0 0">
          <geom type="mesh" mesh="Motor v1" />
          <body name="propeller4" pos="0 0 0.02">
            <joint type="hinge" name="prop_joint4" damping="0.03" axis="0 0 1" />
            <geom type="ellipsoid" size="0.0025 0.015 0.001" rgba="0 0 1 1" />
            <site name="thrust4" pos="0 0 0" />
          </body>
        </body>
      </body>

      <body name="m5" pos="0.020 0 0" >
        <body name="polpusion5"  >
          <geom type="mesh" mesh="Motor v1" />
          <body name="propeller5" pos="0 0 0.02">
            <joint type="hinge" name="prop_joint5" damping="0.03" axis="0 0 1" />
            <geom type="ellipsoid" size="0.0025 0.015 0.001" rgba="0 0 1 1" />
            <site name="thrust5" pos="0 0 0" />
          </body>
        </body>
      </body>

      <body name="m6" pos="-0.020 0 0">
        <body name="polpusion6" >
          <geom type="mesh" mesh="Motor v1" />
          <body name="propeller6" pos="0 0 0.02">
            <joint type="hinge" name="prop_joint6" damping="0.03" axis="0 0 1" />
            <geom type="ellipsoid" size="0.0025 0.015 0.001" rgba="0 0 1 1" />
            <site name="thrust6" pos="0 0 0.02" />
          </body>
        </body> 
      </body>

        <site name="imu" pos="0 0 0" />
        <camera name="blimpCamera" pos="0 -0.01 0" quat=" 1 -1 0 0 " />
      </body>
  </worldbody>

  <actuator>
    <motor name="prop_joint" site="thrust1" />
    <motor name="prop_joint2" site="thrust2" />
    <motor name="prop_joint3" site="thrust3" />
    <motor name="prop_joint4" site="thrust4" />
    <motor name="prop_joint5" site="thrust5" gear="0 0 1 0 0 .0201"/>
    <motor name="prop_joint6" site="thrust6" gear="0 0 1 0 0 .0201"/>
    <!-- <motor name="prop_joint" site="thrust1" gear="0 0 0 0 0 0" /> -->
  </actuator>

  <tendon>
    <spatial range="0 0.0001">
      <site site="mountBalloon1"/>
      <site site="mountGondola1"/>
    </spatial>
    <spatial range="0 0.0001">
      <site site="mountBalloon2"/>
      <site site="mountGondola2"/>
    </spatial>
    <spatial range="0 0.0001">
      <site site="mountBalloon3"/>
      <site site="mountGondola3"/>
    </spatial>
    <spatial range="0 0.0001">
      <site site="mountBalloon4"/>
      <site site="mountGondola4"/>
    </spatial>

  </tendon>

  <sensor>
    <gyro name="body_gyro" site="imu" />
    <accelerometer name="body_linacc" site="imu" />
    <framequat name="body_quat" objtype="site" objname="imu" />
  </sensor>

</mujoco>
